<?xml version="1.0" ?>


<robot name="brokk_v3" xmlns:xacro="http://ros.org/wiki/xacro">

  <xacro:include filename="$(find brokk_description)/urdf/common_properties.xacro"/>
  <xacro:include filename="$(find brokk_description)/urdf/brokk_v3_gazebo.xacro"/>

  <xacro:property name="r200_cam_rgb_px" value="0.005"/>
  <xacro:property name="r200_cam_rgb_py" value="0.018"/>
  <xacro:property name="r200_cam_rgb_pz" value="0.013"/>
  <xacro:property name="r200_cam_depth_offset" value="0.01"/>



  <link name="base_link">
    <origin rpy="0 0 0" xyz="0 0 0.14"/>
    <visual>
      <geometry>
        <box size="0.56 0.34 0.14"/>
      </geometry>
    </visual>
  </link>
  <link name="drum1">
    <origin rpy="1.57079632679 0 0" xyz="0.28 0.22 0.071"/>
    <visual>
      <geometry>
        <cylinder length="0.1" radius="0.07"/>
      </geometry>
    </visual>
  </link>
  <joint name="drum_joint1" type="revolute">
    <origin rpy="0 0 0" xyz="0 0 0"/>
    <parent link="base_link"/>
    <child link="drum1"/>
    <axis xyz="0 1 0"/>
  </joint>
  <link name="drum2">
    <origin rpy="1.57079632679 0 0" xyz="0.28 -0.22 0.071"/>
    <visual>
      <geometry>
        <cylinder length="0.1" radius="0.07"/>
      </geometry>
    </visual>
  </link>
  <joint name="drum_joint2" type="revolute">
    <origin rpy="0 0 0" xyz="0 0 0"/>
    <parent link="base_link"/>
    <child link="drum2"/>
    <axis xyz="0 1 0"/>
  </joint>
  <link name="drum3">
    <origin rpy="1.57079632679 0 0" xyz="-0.28 0.22 0.071"/>
    <visual>
      <geometry>
        <cylinder length="0.1" radius="0.07"/>
      </geometry>
    </visual>
  </link>
  <joint name="drum_joint3" type="revolute">
    <origin rpy="0 0 0" xyz="0 0 0"/>
    <parent link="base_link"/>
    <child link="drum3"/>
    <axis xyz="0 1 0"/>
  </joint>
  <link name="drum4">
    <origin rpy="1.57079632679 0 0" xyz="-0.28 -0.22 0.071"/>
    <visual>
      <geometry>
        <cylinder length="0.1" radius="0.07"/>
      </geometry>
    </visual>
  </link>
  <joint name="drum_joint4" type="revolute">
    <origin rpy="0 0 0" xyz="0 0 0"/>
    <parent link="base_link"/>
    <child link="drum4"/>
    <axis xyz="0 1 0"/>
  </joint>
  <link name="right_pad1">
    <origin rpy="0 0.0 0" xyz="0.0539 0.22000000000000003 0.0005"/>
    <visual>
      <geometry>
        <box size="0.0431 0.1 0.001"/>
      </geometry>
    </visual>
  </link>
  <joint name="right_pad_joint1" type="revolute">
    <origin rpy="0 0 0" xyz="-0.02695 0 0"/>
    <parent link="right_pad1"/>
    <child link="right_pad2"/>
    <axis xyz="0 1 0"/>
  </joint>
  <link name="right_pad2">
    <origin rpy="0 0.0 0" xyz="0.1078 0.22000000000000003 0.0005"/>
    <visual>
      <geometry>
        <box size="0.0431 0.1 0.001"/>
      </geometry>
    </visual>
  </link>
  <joint name="right_pad_joint2" type="revolute">
    <origin rpy="0 0 0" xyz="-0.02695 0 0"/>
    <parent link="right_pad2"/>
    <child link="right_pad3"/>
    <axis xyz="0 1 0"/>
  </joint>
  <link name="right_pad3">
    <origin rpy="0 0.0 0" xyz="0.1617 0.22000000000000003 0.0005"/>
    <visual>
      <geometry>
        <box size="0.0431 0.1 0.001"/>
      </geometry>
    </visual>
  </link>
  <joint name="right_pad_joint3" type="revolute">
    <origin rpy="0 0 0" xyz="-0.02695 0 0"/>
    <parent link="right_pad3"/>
    <child link="right_pad4"/>
    <axis xyz="0 1 0"/>
  </joint>
  <link name="right_pad4">
    <origin rpy="0 0.0 0" xyz="0.2156 0.22000000000000003 0.0005"/>
    <visual>
      <geometry>
        <box size="0.0431 0.1 0.001"/>
      </geometry>
    </visual>
  </link>
  <joint name="right_pad_joint4" type="revolute">
    <origin rpy="0 0 0" xyz="-0.02695 0 0"/>
    <parent link="right_pad4"/>
    <child link="right_pad5"/>
    <axis xyz="0 1 0"/>
  </joint>
  <link name="right_pad5">
    <origin rpy="0 0.0 0" xyz="0.2695 0.22000000000000003 0.0005"/>
    <visual>
      <geometry>
        <box size="0.0431 0.1 0.001"/>
      </geometry>
    </visual>
  </link>
  <joint name="right_pad_joint5" type="revolute">
    <origin rpy="0 0 0" xyz="-0.02695 0 0"/>
    <parent link="right_pad5"/>
    <child link="right_pad6"/>
    <axis xyz="0 1 0"/>
  </joint>
  <link name="right_pad6">
    <origin rpy="0 -0.656178717991 0" xyz="0.31780327599293867 0.22000000000000003 0.01694202251456278"/>
    <visual>
      <geometry>
        <box size="0.0431 0.1 0.001"/>
      </geometry>
    </visual>
  </link>
  <joint name="right_pad_joint6" type="revolute">
    <origin rpy="0 0 0" xyz="-0.02695 0 0"/>
    <parent link="right_pad6"/>
    <child link="right_pad7"/>
    <axis xyz="0 1 0"/>
  </joint>
  <link name="right_pad7">
    <origin rpy="0 -1.31235743598 0" xyz="0.3460442065781305 0.22000000000000003 0.05943903906516046"/>
    <visual>
      <geometry>
        <box size="0.0431 0.1 0.001"/>
      </geometry>
    </visual>
  </link>
  <joint name="right_pad_joint7" type="revolute">
    <origin rpy="0 0 0" xyz="-0.02695 0 0"/>
    <parent link="right_pad7"/>
    <child link="right_pad8"/>
    <axis xyz="0 1 0"/>
  </joint>
  <link name="right_pad8">
    <origin rpy="0 -1.96853615397 0" xyz="0.3424931669549895 0.22000000000000003 0.11034028358446742"/>
    <visual>
      <geometry>
        <box size="0.0431 0.1 0.001"/>
      </geometry>
    </visual>
  </link>
  <joint name="right_pad_joint8" type="revolute">
    <origin rpy="0 0 0" xyz="-0.02695 0 0"/>
    <parent link="right_pad8"/>
    <child link="right_pad9"/>
    <axis xyz="0 1 0"/>
  </joint>
  <link name="right_pad9">
    <origin rpy="0 -2.62471487197 0" xyz="0.3086250505341917 0.22000000000000003 0.14850436704164843"/>
    <visual>
      <geometry>
        <box size="0.0431 0.1 0.001"/>
      </geometry>
    </visual>
  </link>
  <joint name="right_pad_joint9" type="revolute">
    <origin rpy="0 0 0" xyz="-0.02695 0 0"/>
    <parent link="right_pad9"/>
    <child link="right_pad10"/>
    <axis xyz="0 1 0"/>
  </joint>
  <link name="right_pad10">
    <origin rpy="0 3.14159265359 0" xyz="0.25824562832878806 0.22000000000000003 0.1618222000155574"/>
    <visual>
      <geometry>
        <box size="0.0431 0.1 0.001"/>
      </geometry>
    </visual>
  </link>
  <joint name="right_pad_joint10" type="revolute">
    <origin rpy="0 0 0" xyz="-0.02695 0 0"/>
    <parent link="right_pad10"/>
    <child link="right_pad11"/>
    <axis xyz="0 1 0"/>
  </joint>
  <link name="right_pad11">
    <origin rpy="0 3.14159265359 0" xyz="0.20434562832878805 0.22000000000000003 0.16182220001555736"/>
    <visual>
      <geometry>
        <box size="0.0431 0.1 0.001"/>
      </geometry>
    </visual>
  </link>
  <joint name="right_pad_joint11" type="revolute">
    <origin rpy="0 0 0" xyz="-0.02695 0 0"/>
    <parent link="right_pad11"/>
    <child link="right_pad12"/>
    <axis xyz="0 1 0"/>
  </joint>
  <link name="right_pad12">
    <origin rpy="0 3.14159265359 0" xyz="0.15044562832878805 0.22000000000000003 0.1618222000155573"/>
    <visual>
      <geometry>
        <box size="0.0431 0.1 0.001"/>
      </geometry>
    </visual>
  </link>
  <joint name="right_pad_joint12" type="revolute">
    <origin rpy="0 0 0" xyz="-0.02695 0 0"/>
    <parent link="right_pad12"/>
    <child link="right_pad13"/>
    <axis xyz="0 1 0"/>
  </joint>
  <link name="right_pad13">
    <origin rpy="0 3.14159265359 0" xyz="0.09654562832878805 0.22000000000000003 0.16182220001555725"/>
    <visual>
      <geometry>
        <box size="0.0431 0.1 0.001"/>
      </geometry>
    </visual>
  </link>
  <joint name="right_pad_joint13" type="revolute">
    <origin rpy="0 0 0" xyz="-0.02695 0 0"/>
    <parent link="right_pad13"/>
    <child link="right_pad14"/>
    <axis xyz="0 1 0"/>
  </joint>
  <link name="right_pad14">
    <origin rpy="0 3.14159265359 0" xyz="0.04264562832878804 0.22000000000000003 0.1618222000155572"/>
    <visual>
      <geometry>
        <box size="0.0431 0.1 0.001"/>
      </geometry>
    </visual>
  </link>
  <joint name="right_pad_joint14" type="revolute">
    <origin rpy="0 0 0" xyz="-0.02695 0 0"/>
    <parent link="right_pad14"/>
    <child link="right_pad15"/>
    <axis xyz="0 1 0"/>
  </joint>
  <link name="right_pad15">
    <origin rpy="0 3.14159265359 0" xyz="-0.01125437167121196 0.22000000000000003 0.16182220001555714"/>
    <visual>
      <geometry>
        <box size="0.0431 0.1 0.001"/>
      </geometry>
    </visual>
  </link>
  <joint name="right_pad_joint15" type="revolute">
    <origin rpy="0 0 0" xyz="-0.02695 0 0"/>
    <parent link="right_pad15"/>
    <child link="right_pad16"/>
    <axis xyz="0 1 0"/>
  </joint>
  <link name="right_pad16">
    <origin rpy="0 3.14159265359 0" xyz="-0.06515437167121196 0.22000000000000003 0.16182220001555708"/>
    <visual>
      <geometry>
        <box size="0.0431 0.1 0.001"/>
      </geometry>
    </visual>
  </link>
  <joint name="right_pad_joint16" type="revolute">
    <origin rpy="0 0 0" xyz="-0.02695 0 0"/>
    <parent link="right_pad16"/>
    <child link="right_pad17"/>
    <axis xyz="0 1 0"/>
  </joint>
  <link name="right_pad17">
    <origin rpy="0 3.14159265359 0" xyz="-0.11905437167121197 0.22000000000000003 0.16182220001555703"/>
    <visual>
      <geometry>
        <box size="0.0431 0.1 0.001"/>
      </geometry>
    </visual>
  </link>
  <joint name="right_pad_joint17" type="revolute">
    <origin rpy="0 0 0" xyz="-0.02695 0 0"/>
    <parent link="right_pad17"/>
    <child link="right_pad18"/>
    <axis xyz="0 1 0"/>
  </joint>
  <link name="right_pad18">
    <origin rpy="0 3.14159265359 0" xyz="-0.17295437167121197 0.22000000000000003 0.16182220001555697"/>
    <visual>
      <geometry>
        <box size="0.0431 0.1 0.001"/>
      </geometry>
    </visual>
  </link>
  <joint name="right_pad_joint18" type="revolute">
    <origin rpy="0 0 0" xyz="-0.02695 0 0"/>
    <parent link="right_pad18"/>
    <child link="right_pad19"/>
    <axis xyz="0 1 0"/>
  </joint>
  <link name="right_pad19">
    <origin rpy="0 3.14159265359 0" xyz="-0.22685437167121197 0.22000000000000003 0.16182220001555692"/>
    <visual>
      <geometry>
        <box size="0.0431 0.1 0.001"/>
      </geometry>
    </visual>
  </link>
  <joint name="right_pad_joint19" type="revolute">
    <origin rpy="0 0 0" xyz="-0.02695 0 0"/>
    <parent link="right_pad19"/>
    <child link="right_pad20"/>
    <axis xyz="0 1 0"/>
  </joint>
  <link name="right_pad20">
    <origin rpy="0 3.14159265359 0" xyz="-0.280754371671212 0.22000000000000003 0.16182220001555686"/>
    <visual>
      <geometry>
        <box size="0.0431 0.1 0.001"/>
      </geometry>
    </visual>
  </link>
  <joint name="right_pad_joint20" type="revolute">
    <origin rpy="0 0 0" xyz="-0.02695 0 0"/>
    <parent link="right_pad20"/>
    <child link="right_pad21"/>
    <axis xyz="0 1 0"/>
  </joint>
  <link name="right_pad21">
    <origin rpy="0 2.4854139356 0" xyz="-0.32905764766415063 0.22000000000000003 0.14538017750099402"/>
    <visual>
      <geometry>
        <box size="0.0431 0.1 0.001"/>
      </geometry>
    </visual>
  </link>
  <joint name="right_pad_joint21" type="revolute">
    <origin rpy="0 0 0" xyz="-0.02695 0 0"/>
    <parent link="right_pad21"/>
    <child link="right_pad22"/>
    <axis xyz="0 1 0"/>
  </joint>
  <link name="right_pad22">
    <origin rpy="0 1.82923521761 0" xyz="-0.35729857824934236 0.22000000000000003 0.10288316095039632"/>
    <visual>
      <geometry>
        <box size="0.0431 0.1 0.001"/>
      </geometry>
    </visual>
  </link>
  <joint name="right_pad_joint22" type="revolute">
    <origin rpy="0 0 0" xyz="-0.02695 0 0"/>
    <parent link="right_pad22"/>
    <child link="right_pad23"/>
    <axis xyz="0 1 0"/>
  </joint>
  <link name="right_pad23">
    <origin rpy="0 1.17305649962 0" xyz="-0.3537475386262013 0.22000000000000003 0.05198191643108937"/>
    <visual>
      <geometry>
        <box size="0.0431 0.1 0.001"/>
      </geometry>
    </visual>
  </link>
  <joint name="right_pad_joint23" type="revolute">
    <origin rpy="0 0 0" xyz="-0.02695 0 0"/>
    <parent link="right_pad23"/>
    <child link="right_pad24"/>
    <axis xyz="0 1 0"/>
  </joint>
  <link name="right_pad24">
    <origin rpy="0 0.516877781624 0" xyz="-0.31987942220540344 0.22000000000000003 0.01381783297390838"/>
    <visual>
      <geometry>
        <box size="0.0431 0.1 0.001"/>
      </geometry>
    </visual>
  </link>
  <joint name="right_pad_joint24" type="revolute">
    <origin rpy="0 0 0" xyz="-0.02695 0 0"/>
    <parent link="right_pad24"/>
    <child link="right_pad25"/>
    <axis xyz="0 1 0"/>
  </joint>
  <link name="right_pad25">
    <origin rpy="0 -1.66533453694e-15 0" xyz="-0.26949999999999974 0.22000000000000003 0.0004999999999994748"/>
    <visual>
      <geometry>
        <box size="0.0431 0.1 0.001"/>
      </geometry>
    </visual>
  </link>
  <joint name="right_pad_joint25" type="revolute">
    <origin rpy="0 0 0" xyz="-0.02695 0 0"/>
    <parent link="right_pad25"/>
    <child link="right_pad26"/>
    <axis xyz="0 1 0"/>
  </joint>
  <link name="right_pad26">
    <origin rpy="0 -2.1551932566e-15 0" xyz="-0.21559999999999974 0.22000000000000003 0.0004999999999995778"/>
    <visual>
      <geometry>
        <box size="0.0431 0.1 0.001"/>
      </geometry>
    </visual>
  </link>
  <joint name="right_pad_joint26" type="revolute">
    <origin rpy="0 0 0" xyz="-0.02695 0 0"/>
    <parent link="right_pad26"/>
    <child link="right_pad27"/>
    <axis xyz="0 1 0"/>
  </joint>
  <link name="right_pad27">
    <origin rpy="0 -2.1551932566e-15 0" xyz="-0.16169999999999973 0.22000000000000003 0.0004999999999996939"/>
    <visual>
      <geometry>
        <box size="0.0431 0.1 0.001"/>
      </geometry>
    </visual>
  </link>
  <joint name="right_pad_joint27" type="revolute">
    <origin rpy="0 0 0" xyz="-0.02695 0 0"/>
    <parent link="right_pad27"/>
    <child link="right_pad28"/>
    <axis xyz="0 1 0"/>
  </joint>
  <link name="right_pad28">
    <origin rpy="0 -2.1551932566e-15 0" xyz="-0.10779999999999973 0.22000000000000003 0.0004999999999998101"/>
    <visual>
      <geometry>
        <box size="0.0431 0.1 0.001"/>
      </geometry>
    </visual>
  </link>
  <joint name="right_pad_joint28" type="revolute">
    <origin rpy="0 0 0" xyz="-0.02695 0 0"/>
    <parent link="right_pad28"/>
    <child link="right_pad29"/>
    <axis xyz="0 1 0"/>
  </joint>
  <link name="right_pad29">
    <origin rpy="0 -2.1551932566e-15 0" xyz="-0.053899999999999726 0.22000000000000003 0.0004999999999999262"/>
    <visual>
      <geometry>
        <box size="0.0431 0.1 0.001"/>
      </geometry>
    </visual>
  </link>
  <joint name="right_pad_joint29" type="revolute">
    <origin rpy="0 0 0" xyz="-0.02695 0 0"/>
    <parent link="right_pad29"/>
    <child link="right_pad30"/>
    <axis xyz="0 1 0"/>
  </joint>
  <link name="right_pad30">
    <origin rpy="0 -2.1551932566e-15 0" xyz="2.7755575615628914e-16 0.22000000000000003 0.0005000000000000423"/>
    <visual>
      <geometry>
        <box size="0.0431 0.1 0.001"/>
      </geometry>
    </visual>
  </link>
  <joint name="right_pad_joint30" type="revolute">
    <origin rpy="0 0 0" xyz="-0.02695 0 0"/>
    <parent link="right_pad30"/>
    <child link="right_pad31"/>
    <axis xyz="0 1 0"/>
  </joint>
  <link name="right_pad31">
    <origin rpy="0 -2.1551932566e-15 0" xyz="0.05390000000000028 0.22000000000000003 0.0005000000000001584"/>
    <visual>
      <geometry>
        <box size="0.0431 0.1 0.001"/>
      </geometry>
    </visual>
  </link>
  <joint name="right_pad_joint31" type="revolute">
    <origin rpy="0 0 0" xyz="-0.02695 0 0"/>
    <parent link="right_pad31"/>
    <child link="right_pad1"/>
    <axis xyz="0 1 0"/>
  </joint>
  <link name="left_pad1">
    <origin rpy="0 0.0 0" xyz="0.0539 -0.22000000000000003 0.0005"/>
    <visual>
      <geometry>
        <box size="0.0431 0.1 0.001"/>
      </geometry>
    </visual>
  </link>
  <joint name="left_pad_joint1" type="revolute">
    <origin rpy="0 0 0" xyz="-0.02695 0 0"/>
    <parent link="left_pad1"/>
    <child link="left_pad2"/>
    <axis xyz="0 1 0"/>
  </joint>
  <link name="left_pad2">
    <origin rpy="0 0.0 0" xyz="0.1078 -0.22000000000000003 0.0005"/>
    <visual>
      <geometry>
        <box size="0.0431 0.1 0.001"/>
      </geometry>
    </visual>
  </link>
  <joint name="left_pad_joint2" type="revolute">
    <origin rpy="0 0 0" xyz="-0.02695 0 0"/>
    <parent link="left_pad2"/>
    <child link="left_pad3"/>
    <axis xyz="0 1 0"/>
  </joint>
  <link name="left_pad3">
    <origin rpy="0 0.0 0" xyz="0.1617 -0.22000000000000003 0.0005"/>
    <visual>
      <geometry>
        <box size="0.0431 0.1 0.001"/>
      </geometry>
    </visual>
  </link>
  <joint name="left_pad_joint3" type="revolute">
    <origin rpy="0 0 0" xyz="-0.02695 0 0"/>
    <parent link="left_pad3"/>
    <child link="left_pad4"/>
    <axis xyz="0 1 0"/>
  </joint>
  <link name="left_pad4">
    <origin rpy="0 0.0 0" xyz="0.2156 -0.22000000000000003 0.0005"/>
    <visual>
      <geometry>
        <box size="0.0431 0.1 0.001"/>
      </geometry>
    </visual>
  </link>
  <joint name="left_pad_joint4" type="revolute">
    <origin rpy="0 0 0" xyz="-0.02695 0 0"/>
    <parent link="left_pad4"/>
    <child link="left_pad5"/>
    <axis xyz="0 1 0"/>
  </joint>
  <link name="left_pad5">
    <origin rpy="0 0.0 0" xyz="0.2695 -0.22000000000000003 0.0005"/>
    <visual>
      <geometry>
        <box size="0.0431 0.1 0.001"/>
      </geometry>
    </visual>
  </link>
  <joint name="left_pad_joint5" type="revolute">
    <origin rpy="0 0 0" xyz="-0.02695 0 0"/>
    <parent link="left_pad5"/>
    <child link="left_pad6"/>
    <axis xyz="0 1 0"/>
  </joint>
  <link name="left_pad6">
    <origin rpy="0 -0.656178717991 0" xyz="0.31780327599293867 -0.22000000000000003 0.01694202251456278"/>
    <visual>
      <geometry>
        <box size="0.0431 0.1 0.001"/>
      </geometry>
    </visual>
  </link>
  <joint name="left_pad_joint6" type="revolute">
    <origin rpy="0 0 0" xyz="-0.02695 0 0"/>
    <parent link="left_pad6"/>
    <child link="left_pad7"/>
    <axis xyz="0 1 0"/>
  </joint>
  <link name="left_pad7">
    <origin rpy="0 -1.31235743598 0" xyz="0.3460442065781305 -0.22000000000000003 0.05943903906516046"/>
    <visual>
      <geometry>
        <box size="0.0431 0.1 0.001"/>
      </geometry>
    </visual>
  </link>
  <joint name="left_pad_joint7" type="revolute">
    <origin rpy="0 0 0" xyz="-0.02695 0 0"/>
    <parent link="left_pad7"/>
    <child link="left_pad8"/>
    <axis xyz="0 1 0"/>
  </joint>
  <link name="left_pad8">
    <origin rpy="0 -1.96853615397 0" xyz="0.3424931669549895 -0.22000000000000003 0.11034028358446742"/>
    <visual>
      <geometry>
        <box size="0.0431 0.1 0.001"/>
      </geometry>
    </visual>
  </link>
  <joint name="left_pad_joint8" type="revolute">
    <origin rpy="0 0 0" xyz="-0.02695 0 0"/>
    <parent link="left_pad8"/>
    <child link="left_pad9"/>
    <axis xyz="0 1 0"/>
  </joint>
  <link name="left_pad9">
    <origin rpy="0 -2.62471487197 0" xyz="0.3086250505341917 -0.22000000000000003 0.14850436704164843"/>
    <visual>
      <geometry>
        <box size="0.0431 0.1 0.001"/>
      </geometry>
    </visual>
  </link>
  <joint name="left_pad_joint9" type="revolute">
    <origin rpy="0 0 0" xyz="-0.02695 0 0"/>
    <parent link="left_pad9"/>
    <child link="left_pad10"/>
    <axis xyz="0 1 0"/>
  </joint>
  <link name="left_pad10">
    <origin rpy="0 3.14159265359 0" xyz="0.25824562832878806 -0.22000000000000003 0.1618222000155574"/>
    <visual>
      <geometry>
        <box size="0.0431 0.1 0.001"/>
      </geometry>
    </visual>
  </link>
  <joint name="left_pad_joint10" type="revolute">
    <origin rpy="0 0 0" xyz="-0.02695 0 0"/>
    <parent link="left_pad10"/>
    <child link="left_pad11"/>
    <axis xyz="0 1 0"/>
  </joint>
  <link name="left_pad11">
    <origin rpy="0 3.14159265359 0" xyz="0.20434562832878805 -0.22000000000000003 0.16182220001555736"/>
    <visual>
      <geometry>
        <box size="0.0431 0.1 0.001"/>
      </geometry>
    </visual>
  </link>
  <joint name="left_pad_joint11" type="revolute">
    <origin rpy="0 0 0" xyz="-0.02695 0 0"/>
    <parent link="left_pad11"/>
    <child link="left_pad12"/>
    <axis xyz="0 1 0"/>
  </joint>
  <link name="left_pad12">
    <origin rpy="0 3.14159265359 0" xyz="0.15044562832878805 -0.22000000000000003 0.1618222000155573"/>
    <visual>
      <geometry>
        <box size="0.0431 0.1 0.001"/>
      </geometry>
    </visual>
  </link>
  <joint name="left_pad_joint12" type="revolute">
    <origin rpy="0 0 0" xyz="-0.02695 0 0"/>
    <parent link="left_pad12"/>
    <child link="left_pad13"/>
    <axis xyz="0 1 0"/>
  </joint>
  <link name="left_pad13">
    <origin rpy="0 3.14159265359 0" xyz="0.09654562832878805 -0.22000000000000003 0.16182220001555725"/>
    <visual>
      <geometry>
        <box size="0.0431 0.1 0.001"/>
      </geometry>
    </visual>
  </link>
  <joint name="left_pad_joint13" type="revolute">
    <origin rpy="0 0 0" xyz="-0.02695 0 0"/>
    <parent link="left_pad13"/>
    <child link="left_pad14"/>
    <axis xyz="0 1 0"/>
  </joint>
  <link name="left_pad14">
    <origin rpy="0 3.14159265359 0" xyz="0.04264562832878804 -0.22000000000000003 0.1618222000155572"/>
    <visual>
      <geometry>
        <box size="0.0431 0.1 0.001"/>
      </geometry>
    </visual>
  </link>
  <joint name="left_pad_joint14" type="revolute">
    <origin rpy="0 0 0" xyz="-0.02695 0 0"/>
    <parent link="left_pad14"/>
    <child link="left_pad15"/>
    <axis xyz="0 1 0"/>
  </joint>
  <link name="left_pad15">
    <origin rpy="0 3.14159265359 0" xyz="-0.01125437167121196 -0.22000000000000003 0.16182220001555714"/>
    <visual>
      <geometry>
        <box size="0.0431 0.1 0.001"/>
      </geometry>
    </visual>
  </link>
  <joint name="left_pad_joint15" type="revolute">
    <origin rpy="0 0 0" xyz="-0.02695 0 0"/>
    <parent link="left_pad15"/>
    <child link="left_pad16"/>
    <axis xyz="0 1 0"/>
  </joint>
  <link name="left_pad16">
    <origin rpy="0 3.14159265359 0" xyz="-0.06515437167121196 -0.22000000000000003 0.16182220001555708"/>
    <visual>
      <geometry>
        <box size="0.0431 0.1 0.001"/>
      </geometry>
    </visual>
  </link>
  <joint name="left_pad_joint16" type="revolute">
    <origin rpy="0 0 0" xyz="-0.02695 0 0"/>
    <parent link="left_pad16"/>
    <child link="left_pad17"/>
    <axis xyz="0 1 0"/>
  </joint>
  <link name="left_pad17">
    <origin rpy="0 3.14159265359 0" xyz="-0.11905437167121197 -0.22000000000000003 0.16182220001555703"/>
    <visual>
      <geometry>
        <box size="0.0431 0.1 0.001"/>
      </geometry>
    </visual>
  </link>
  <joint name="left_pad_joint17" type="revolute">
    <origin rpy="0 0 0" xyz="-0.02695 0 0"/>
    <parent link="left_pad17"/>
    <child link="left_pad18"/>
    <axis xyz="0 1 0"/>
  </joint>
  <link name="left_pad18">
    <origin rpy="0 3.14159265359 0" xyz="-0.17295437167121197 -0.22000000000000003 0.16182220001555697"/>
    <visual>
      <geometry>
        <box size="0.0431 0.1 0.001"/>
      </geometry>
    </visual>
  </link>
  <joint name="left_pad_joint18" type="revolute">
    <origin rpy="0 0 0" xyz="-0.02695 0 0"/>
    <parent link="left_pad18"/>
    <child link="left_pad19"/>
    <axis xyz="0 1 0"/>
  </joint>
  <link name="left_pad19">
    <origin rpy="0 3.14159265359 0" xyz="-0.22685437167121197 -0.22000000000000003 0.16182220001555692"/>
    <visual>
      <geometry>
        <box size="0.0431 0.1 0.001"/>
      </geometry>
    </visual>
  </link>
  <joint name="left_pad_joint19" type="revolute">
    <origin rpy="0 0 0" xyz="-0.02695 0 0"/>
    <parent link="left_pad19"/>
    <child link="left_pad20"/>
    <axis xyz="0 1 0"/>
  </joint>
  <link name="left_pad20">
    <origin rpy="0 3.14159265359 0" xyz="-0.280754371671212 -0.22000000000000003 0.16182220001555686"/>
    <visual>
      <geometry>
        <box size="0.0431 0.1 0.001"/>
      </geometry>
    </visual>
  </link>
  <joint name="left_pad_joint20" type="revolute">
    <origin rpy="0 0 0" xyz="-0.02695 0 0"/>
    <parent link="left_pad20"/>
    <child link="left_pad21"/>
    <axis xyz="0 1 0"/>
  </joint>
  <link name="left_pad21">
    <origin rpy="0 2.4854139356 0" xyz="-0.32905764766415063 -0.22000000000000003 0.14538017750099402"/>
    <visual>
      <geometry>
        <box size="0.0431 0.1 0.001"/>
      </geometry>
    </visual>
  </link>
  <joint name="left_pad_joint21" type="revolute">
    <origin rpy="0 0 0" xyz="-0.02695 0 0"/>
    <parent link="left_pad21"/>
    <child link="left_pad22"/>
    <axis xyz="0 1 0"/>
  </joint>
  <link name="left_pad22">
    <origin rpy="0 1.82923521761 0" xyz="-0.35729857824934236 -0.22000000000000003 0.10288316095039632"/>
    <visual>
      <geometry>
        <box size="0.0431 0.1 0.001"/>
      </geometry>
    </visual>
  </link>
  <joint name="left_pad_joint22" type="revolute">
    <origin rpy="0 0 0" xyz="-0.02695 0 0"/>
    <parent link="left_pad22"/>
    <child link="left_pad23"/>
    <axis xyz="0 1 0"/>
  </joint>
  <link name="left_pad23">
    <origin rpy="0 1.17305649962 0" xyz="-0.3537475386262013 -0.22000000000000003 0.05198191643108937"/>
    <visual>
      <geometry>
        <box size="0.0431 0.1 0.001"/>
      </geometry>
    </visual>
  </link>
  <joint name="left_pad_joint23" type="revolute">
    <origin rpy="0 0 0" xyz="-0.02695 0 0"/>
    <parent link="left_pad23"/>
    <child link="left_pad24"/>
    <axis xyz="0 1 0"/>
  </joint>
  <link name="left_pad24">
    <origin rpy="0 0.516877781624 0" xyz="-0.31987942220540344 -0.22000000000000003 0.01381783297390838"/>
    <visual>
      <geometry>
        <box size="0.0431 0.1 0.001"/>
      </geometry>
    </visual>
  </link>
  <joint name="left_pad_joint24" type="revolute">
    <origin rpy="0 0 0" xyz="-0.02695 0 0"/>
    <parent link="left_pad24"/>
    <child link="left_pad25"/>
    <axis xyz="0 1 0"/>
  </joint>
  <link name="left_pad25">
    <origin rpy="0 -1.66533453694e-15 0" xyz="-0.26949999999999974 -0.22000000000000003 0.0004999999999994748"/>
    <visual>
      <geometry>
        <box size="0.0431 0.1 0.001"/>
      </geometry>
    </visual>
  </link>
  <joint name="left_pad_joint25" type="revolute">
    <origin rpy="0 0 0" xyz="-0.02695 0 0"/>
    <parent link="left_pad25"/>
    <child link="left_pad26"/>
    <axis xyz="0 1 0"/>
  </joint>
  <link name="left_pad26">
    <origin rpy="0 -2.1551932566e-15 0" xyz="-0.21559999999999974 -0.22000000000000003 0.0004999999999995778"/>
    <visual>
      <geometry>
        <box size="0.0431 0.1 0.001"/>
      </geometry>
    </visual>
  </link>
  <joint name="left_pad_joint26" type="revolute">
    <origin rpy="0 0 0" xyz="-0.02695 0 0"/>
    <parent link="left_pad26"/>
    <child link="left_pad27"/>
    <axis xyz="0 1 0"/>
  </joint>
  <link name="left_pad27">
    <origin rpy="0 -2.1551932566e-15 0" xyz="-0.16169999999999973 -0.22000000000000003 0.0004999999999996939"/>
    <visual>
      <geometry>
        <box size="0.0431 0.1 0.001"/>
      </geometry>
    </visual>
  </link>
  <joint name="left_pad_joint27" type="revolute">
    <origin rpy="0 0 0" xyz="-0.02695 0 0"/>
    <parent link="left_pad27"/>
    <child link="left_pad28"/>
    <axis xyz="0 1 0"/>
  </joint>
  <link name="left_pad28">
    <origin rpy="0 -2.1551932566e-15 0" xyz="-0.10779999999999973 -0.22000000000000003 0.0004999999999998101"/>
    <visual>
      <geometry>
        <box size="0.0431 0.1 0.001"/>
      </geometry>
    </visual>
  </link>
  <joint name="left_pad_joint28" type="revolute">
    <origin rpy="0 0 0" xyz="-0.02695 0 0"/>
    <parent link="left_pad28"/>
    <child link="left_pad29"/>
    <axis xyz="0 1 0"/>
  </joint>
  <link name="left_pad29">
    <origin rpy="0 -2.1551932566e-15 0" xyz="-0.053899999999999726 -0.22000000000000003 0.0004999999999999262"/>
    <visual>
      <geometry>
        <box size="0.0431 0.1 0.001"/>
      </geometry>
    </visual>
  </link>
  <joint name="left_pad_joint29" type="revolute">
    <origin rpy="0 0 0" xyz="-0.02695 0 0"/>
    <parent link="left_pad29"/>
    <child link="left_pad30"/>
    <axis xyz="0 1 0"/>
  </joint>
  <link name="left_pad30">
    <origin rpy="0 -2.1551932566e-15 0" xyz="2.7755575615628914e-16 -0.22000000000000003 0.0005000000000000423"/>
    <visual>
      <geometry>
        <box size="0.0431 0.1 0.001"/>
      </geometry>
    </visual>
  </link>
  <joint name="left_pad_joint30" type="revolute">
    <origin rpy="0 0 0" xyz="-0.02695 0 0"/>
    <parent link="left_pad30"/>
    <child link="left_pad31"/>
    <axis xyz="0 1 0"/>
  </joint>
  <link name="left_pad31">
    <origin rpy="0 -2.1551932566e-15 0" xyz="0.05390000000000028 -0.22000000000000003 0.0005000000000001584"/>
    <visual>
      <geometry>
        <box size="0.0431 0.1 0.001"/>
      </geometry>
    </visual>
  </link>
  <joint name="left_pad_joint31" type="revolute">
    <origin rpy="0 0 0" xyz="-0.02695 0 0"/>
    <parent link="left_pad31"/>
    <child link="left_pad1"/>
    <axis xyz="0 1 0"/>
  </joint>
  
 <joint name="imu_joint" type="fixed">
  <parent link="base_link"/>
  <child link="imu_link"/>
  <origin xyz="0.0 0 -0.022" rpy="0 0 0"/>
 </joint>

 <link name="imu_link"/>
 
</robot>
