<?xml version="1.0"?>
<robot name="brokk_vH" xmlns:xacro="http://ros.org/wiki/xacro">

  <xacro:property name="joint_damping" value="100"/>
  <xacro:property name="PI" value="3.1415926535897931"/>
  <xacro:property name="mass" value="1" /> <!-- arbitrary value for mass -->
  <xacro:property name="width" value="0.1" /> <!-- Square dimensions (widthxwidth) of beams -->
  <xacro:property name="height1" value="2" /> <!-- Link 1 -->
  <xacro:property name="height2" value="1" /> <!-- Link 2 -->
  <xacro:property name="height3" value="1" /> <!-- Link 3 -->

  <xacro:property name="r200_cam_rgb_px" value="0.005"/>
  <xacro:property name="r200_cam_rgb_py" value="0.018"/>
  <xacro:property name="r200_cam_rgb_pz" value="0.013"/>
  <xacro:property name="r200_cam_depth_offset" value="0.01"/>

    <!--constant things-->
  <xacro:macro name="brokk_arm" params="prefix joint_limited
    brokk_base_lower_limit:=${0.152}     brokk_base_upper_limit:=${2.983}
    brokk_body1_lower_limit:=${0.2513}    brokk_body1_upper_limit:=${2.2617}
    brokk_body2_lower_limit:=${0.076}    brokk_body2_upper_limit:=${1.444}
    brokk_body3_lower_limit:=${0.096}    brokk_body3_upper_limit:=${1.824}
    brokk_body4_lower_limit:=${0.128}    brokk_body4_upper_limit:=${2.4367}
    safety_limits:=true safety_pos_margin:=0.15
    brokk_arm_vel_limit:=50.0
    k_velocity :=1.0
    description_pkg:='brokk_arm_description'">

  <link name="base_footprint"/>  <!--world footprint-->

  <link name="base_link">       <!--robot base??-->
  <visual>
        <origin xyz="0.05 0 0" rpy="0 0 0" />
        <geometry>
            <mesh filename="package://brokk/description/brokk_hishversion/meshfiles/legs_final2.dae" />
        </geometry>
        <material name="LightGrey">
            <color rgba="0.7 0.7 0.7 1.0"/>
        </material>
    </visual>

    <collision>
        <origin xyz="-0.064 0 0.047" rpy="0 0 0"/>
        <geometry>
            <mesh scale="0.0011 0.001 0.001" filename="package://brokk/description/brokk_hishversion/meshfiles/legs.stl" />
        </geometry>
    </collision>

    </link> 
    
    <!--robot base??-->


    <link name="brokk_base">
        <visual>
            <origin xyz="0 0 0.0" rpy="0 0 0" />
            <geometry>
                <mesh filename="package://brokk/description/brokk_hishversion/meshfiles/base_final2.dae" />
            </geometry>
            <material name="LightGrey">
                <color rgba="0.7 0.7 0.7 1.0"/>
            </material>      
        </visual>

        <collision>
            <origin xyz="0 0 0" rpy="0 0 0" />
            <geometry>
                <mesh scale="0.001 0.001 0.001"  filename="package://brokk/description/brokk_hishversion/meshfiles/base.stl" />
            </geometry>
        </collision>

        <inertial>
            <origin xyz="0 0 0" rpy="0 0 0" />
            <mass value="2.34"/>
            <inertia ixx="1.0" ixy="0.0" ixz="0.0" iyy="1.0" iyz="0.0" izz="1.0" />
        </inertial>

    </link>

    <joint name="brokk_base_joint" type="revolute"> <!--not really sure which joint exactly-->
      <parent link="base_footprint" />
      <child link = "base_link" />
      <origin xyz="0 0.0 0.59" rpy="0.0 0.0 1.57" />
      <axis xyz="0 0 -1" />
      <limit effort="100.0" lower="${brokk_base_lower_limit}" upper="${brokk_base_upper_limit}" velocity="${brokk_arm_vel_limit}"/>
      <dynamics damping="${joint_damping}"/>
    </joint>

    <!-- also not sure which link _______________________________________________________________________________ -->
    <link name="brokk_body1">
        <visual>
            <geometry>
            <mesh  filename="package://brokk/description/brokk_hishversion/meshfiles/body1.dae"  />
            </geometry>
            <material name="LightGrey">
            <color rgba="0.7 0.7 0.7 1.0"/>
            </material>
        </visual>

        <collision>
        <origin xyz="0 0 0" rpy="0 0 0" />
            <geometry>
            <mesh scale="0.001 0.001 0.001" filename="package://brokk/description/brokk_hishversion/meshfiles/body1.stl" />
            </geometry>
        </collision>

        <inertial>
            <origin xyz="0 0 0" rpy="0 0 0" />
            <mass value="2.34"/>
            <inertia ixx="1.0" ixy="0.0" ixz="0.0" iyy="1.0" iyz="0.0" izz="1.0" />
        </inertial>
    </link>

    <!--body1 joint _______________________________________________________________________________________________ -->
    <joint name="brokk_jnt1" type="revolute">
        <parent link="$brokk_base" />
        <child link = "brokk_body1" />
        <origin xyz="0.493 0 0.078" rpy="0.0 -0.806 0.0" />
        <axis xyz="0 1 0" />
        <limit effort="100.0" lower="${brokk_body1_lower_limit}" upper="${brokk_body1_upper_limit}" velocity="${brokk_arm_vel_limit}"/>
        <dynamics damping="${joint_damping}"/>
    </joint>

    <!--body2 link ________________________________________________________________________________________________ -->
    <link name="brokk_body2">
        <visual>
            <geometry>
                <mesh filename="package://brokk/description/brokk_hishversion/meshfiles/body2.dae" />
            </geometry>
            <material name="LightGrey">
                <color rgba="0.7 0.7 0.7 1.0"/>
            </material>
        </visual>

        <collision>
	        <origin xyz="0 0 0" rpy="0 0 0" />
            <geometry>
                <mesh scale="0.001 0.001 0.001" filename="package://brokk/description/brokk_hishversion/meshfiles/body2.stl" />
            </geometry>
        </collision>

        <inertial>
            <origin xyz="0 0 0" rpy="0 0 0" />
            <mass value="2.34"/>
            <inertia ixx="1.0" ixy="0.0" ixz="0.0" iyy="1.0" iyz="0.0" izz="1.0" />
        </inertial>
    </link>

    <!--body2 joint _________________________________________________________________________________________________ -->
    <joint name="brokk_jnt2" type="revolute">
      <parent link="brokk_body1" />
      <child link ="brokk_body2" />
      <origin xyz="0 0 0.87" rpy="0.0 0.78 0.0" />
      <axis xyz="0 -1 0" />
      <limit effort="100.0" lower="${brokk_body2_lower_limit }" upper="${brokk_body2_upper_limit }" velocity="0.5"/>
      <dynamics damping="${joint_damping}"/>
    </joint>

    <!--body3 link __________________________________________________________________________________________________ -->
    <link name="${prefix}brokk_body3">
        <visual>
            <geometry>
                <mesh  filename="package://brokk/description/brokk_hishversion/meshfiles/body3.dae" />
            </geometry>
            <material name="LightGrey">
                <color rgba="0.7 0.7 0.7 1.0"/>
            </material>
        </visual>

        <collision>
            <origin xyz="0 0 0" rpy="0 0 0" />
            <geometry>
                <mesh scale="0.001 0.001 0.001" filename="package://brokk/description/brokk_hishversion/meshfiles/body3.stl" />
            </geometry>
        </collision>

        <inertial>
            <origin xyz="0 0 0" rpy="0 0 0" />
            <mass value="2.34"/>
            <inertia ixx="1.0" ixy="0.0" ixz="0.0" iyy="1.0" iyz="0.0" izz="1.0" />
        </inertial>
    </link>

    <!--body3 joint  __________________________________________________________________________________________________ -->
    <joint name="$brokk_jnt3" type="revolute">
        <parent link="brokk_body2" />
        <child link ="brokk_body3" />
        <origin xyz="1.37 0.0 0.01" rpy="0.0 1.75 0.0" />
        <axis xyz="0 -1 0" />
        <limit effort="100.0" lower="${brokk_body3_lower_limit }" upper="${brokk_body3_upper_limit }" velocity="0.5"/>
        <dynamics damping="${joint_damping}"/>
    </joint>

    <!--body4 link _____________________________________________________________________________________________________ -->
    <link name="$brokk_body4">
        <visual>
            <geometry>
                <mesh  filename="package://brokk/description/brokk_hishversion/meshfiles/body4.dae"/>
            </geometry>
            <material name="LightGrey">
                <color rgba="0.7 0.7 0.7 1.0"/>
            </material>
        </visual>

        <collision>
	        <origin xyz=" 0 0 0" rpy="0 0 0" />
            <geometry>
                <mesh scale="0.001 0.001 0.001" filename="package://brokk/description/brokk_hishversion/meshfiles/body4.stl" />
            </geometry>
        </collision>

        <inertial>
            <origin xyz="0 0 0" rpy="0 0 0" />
            <mass value="2.34"/>
            <inertia ixx="1.0" ixy="0.0" ixz="0.0" iyy="1.0" iyz="0.0" izz="1.0" />
        </inertial>
    </link>

    <!--joint of body4___________________________________________________________________________________________________________ -->
    <joint name="brokk_jnt4" type="revolute">
      <parent link="brokk_body3" />
      <child link ="brokk_body4" />
      <origin xyz="0.89 0 0.0" rpy="0.0 -1.19 0.0" />
      <axis xyz="0 1 0" />
      <limit effort="100.0" lower="${brokk_body4_lower_limit }" upper="${brokk_body4_upper_limit }" velocity="2"/>
     <dynamics damping="${joint_damping}"/>
    </joint>


    <!--EINHEIT: SPITZE___________________________________________________________________________________________________________-->

        <!-- brokk tip link ___________________________________________________________________________________________________________ -->

    <link name="brokk_tip">
        <visual>
            <geometry>
                <mesh scale="0.01 0.01 0.01" filename="package://brokk/description/tip.STL" />
            </geometry>
            <material name="LightGrey">
                <color rgba="0.7 0.7 0.7 1.0"/>
            </material>
        </visual>

        <collision>
            <origin xyz="0 0 0" rpy="0 0 0" />
            <geometry>
                <mesh scale="0.01 0.01 0.01" filename="package://brokk/description/tip.STL" />
            </geometry>
        </collision>

        <inertial>
            <origin xyz="0 0 0" rpy="0 0 0" />
            <mass value="2.34"/>
            <inertia ixx="1.0" ixy="0.0" ixz="0.0" iyy="1.0" iyz="0.0" izz="1.0" />
        </inertial>
    </link>

    <!--tip joint _________________________________________________________________________________________________________________ -->
    <joint name="brokk_tip_jnt" type="fixed">
      <parent link="brokk_arm4" />
      <child link ="brokk_tip" />
      <origin xyz="1.25 0 0.08" rpy="0.0 0.0 0.0" />		
      <axis xyz="0 1 0" />
      <limit effort="0" lower="0" upper="0" velocity="0"/>
      <dynamics damping="${joint_damping}"/>
    </joint>



  </xacro:macro>
</robot>


