<robot
  name="brokk_arm_description">
  <link
    name="dummy2">
    <visual>
      <origin
        xyz="0 0 0"
        rpy="0 0 0" />
    <geometry>
        <mesh scale="0.001 0.001 0.001" filename="root.STL" />
      </geometry>
      <material
        name="">
        <color
          rgba="0.75294 0.75294 0.75294 1" />
      </material>
    </visual>
    <inertial>
      <mass value="1.0" />
      <inertia ixx="1.0" ixy="0.0" ixz="0.0" iyy="1.0" iyz="0.0" izz="1.0" />
    </inertial>
    <collision>
      <origin
        xyz="0 0 0"
        rpy="0 0 0" />
      <geometry>
        <mesh scale="0.001 0.001 0.001" filename="root.STL" />
      </geometry>
    </collision>
  </link>
  <link
    name="base">
    <visual>
      <origin
        xyz="0 0 0"
        rpy="0 0 0" />
      <geometry>
        <mesh scale="0.001 0.001 0.001" filename="base.STL" />
      </geometry>
      <material
        name="">
        <color
          rgba="0.75294 0.75294 0.75294 1" />
      </material>
    </visual>
    <inertial>
      <mass value="1.0" />
      <inertia ixx="1.0" ixy="0.0" ixz="0.0" iyy="1.0" iyz="0.0" izz="1.0" />
    </inertial>
    <collision>
      <origin
        xyz="0 0 0"
        rpy="0 0 0" />
      <geometry>
        <mesh scale="0.001 0.001 0.001" filename="base.STL" />
      </geometry>
    </collision>
  </link>
   <joint
    name="jnt0"
    type="revolute">
    <origin
      xyz="0 0 0"
      rpy="0 0 0" />
    <parent
      link="dummy2" />
    <child
      link="base" />
    <axis
      xyz="0 0 1" />
    <limit
      lower="-785"
      upper="157"
      effort="1"
      velocity="1" />
    <dynamics
      damping="1"
      friction="1" />
  </joint>
  <link
    name="body1">
    <visual>
      <origin
        xyz="0 0 0"
        rpy="0 0 0" />
      <geometry>
        <mesh scale="0.001 0.001 0.001" filename="body1.STL" />
      </geometry>
      <material
        name="">
        <color
          rgba="0.64314 0.63529 0.65098 1" />
      </material>
    </visual>
    <inertial>
      <mass value="1.0" />
      <inertia ixx="1.0" ixy="0.0" ixz="0.0" iyy="1.0" iyz="0.0" izz="1.0" />
    </inertial>
    <collision>
      <origin
        xyz="0 0 0"
        rpy="0 0 0" />
      <geometry>
        <mesh scale="0.001 0.001 0.001" filename="body1.STL" />
      </geometry>
    </collision>
  </link>
  <joint
    name="jnt1"
    type="revolute">
    <origin
      xyz="0.56 0 0"
      rpy="0 0 0" />
    <parent
      link="base" />
    <child
      link="body1" />
    <axis
      xyz="0 1 0" />
    <limit
      lower="-785"
      upper="785"
      effort="1"
      velocity="1" />
    <dynamics
      damping="1"
      friction="1" />
  </joint>
  <link
    name="body2">
    <visual>
      <origin
        xyz="0 0 0"
        rpy="0 0 0" />
      <geometry>
        <mesh scale="0.001 0.001 0.001" filename="body2.STL" />
      </geometry>
      <material
        name="">
        <color
          rgba="0.64314 0.63529 0.65098 1" />
      </material>
    </visual>
    <inertial>
      <mass value="1.0" />
      <inertia ixx="1.0" ixy="0.0" ixz="0.0" iyy="1.0" iyz="0.0" izz="1.0" />
    </inertial>
    <collision>
      <origin
        xyz="0 0 0"
        rpy="0 0 0" />
      <geometry>
        <mesh scale="0.001 0.001 0.001" filename="body2.STL" />
      </geometry>
    </collision>
  </link>
  <joint
    name="jnt2"
    type="revolute">
    <origin
      xyz="-0.14 0 0.9"
      rpy="0 0 0" />
    <parent
      link="body1" />
    <child
      link="body2" />
    <axis
      xyz="0 1 0" />
    <limit
      lower="-157"
      upper="157"
      effort="1"
      velocity="1" />
    <dynamics
      damping="1"
      friction="1" />
  </joint>
  <link
    name="body3">
    <visual>
      <origin
        xyz="0 0 0"
        rpy="0 0 0" />
      <geometry>
        <mesh scale="0.001 0.001 0.001" filename="body3.STL" />
      </geometry>
      <material
        name="">
        <color
          rgba="0.64314 0.63529 0.65098 1" />
      </material>
    </visual>
    <inertial>
      <mass value="1.0" />
      <inertia ixx="1.0" ixy="0.0" ixz="0.0" iyy="1.0" iyz="0.0" izz="1.0" />
    </inertial>
    <collision>
      <origin
        xyz="0 0 0"
        rpy="0 0 0" />
      <geometry>
        <mesh scale="0.001 0.001 0.001" filename="body3.STL" />
      </geometry>
    </collision>
  </link>
  <joint
    name="jnt3"
    type="revolute">
    <origin
      xyz="1.4 0 0"
      rpy="0 0 0" />
    <parent
      link="body2" />
    <child
      link="body3" />
    <axis
      xyz="0 1 0" />
    <limit
      lower="-157"
      upper="157"
      effort="1"
      velocity="1" />
    <dynamics
      damping="1"
      friction="1" />
  </joint>
  <link
    name="body4">
    <visual>
      <origin
        xyz="0 0 0"
        rpy="0 0 0" />
      <geometry>
        <mesh scale="0.001 0.001 0.001" filename="body4.STL" />
      </geometry>
      <material
        name="">
        <color
          rgba="0.87843 0.87451 0.85882 1" />
      </material>
    </visual>
    <inertial>
      <mass value="1.0" />
      <inertia ixx="1.0" ixy="0.0" ixz="0.0" iyy="1.0" iyz="0.0" izz="1.0" />
    </inertial>
    <collision>
      <origin
        xyz="0 0 0"
        rpy="0 0 0" />
      <geometry>
        <mesh scale="0.001 0.001 0.001" filename="body4.STL" />
      </geometry>
    </collision>
  </link>
  <joint
    name="jnt4"
    type="revolute">
    <origin
      xyz="0.89 0 0"
      rpy="0 0 0" />
    <parent
      link="body3" />
    <child
      link="body4" />
    <axis
      xyz="0 1 0" />
    <limit
      lower="-785"
      upper="157"
      effort="1"
      velocity="1" />
    <dynamics
      damping="1"
      friction="1" />
  </joint>
</robot>
